Workbook
Name A_IMPRESIÓN_IM: #REF!
Name AA: #REF!
Name Actual: #REF!
Name afasf: #REF!
Name aff: #REF!
Name Ale: [1]MATRIZ!#REF!
Name alejandra: #REF!
Name algodur: #REF!
Name algodur2: #REF!
Name area: [2]weights1!$B$1:$T$59
Name asasas: #REF!
Name asasas2: #REF!
Name banco: '[3]BASE '!$C$2:$C$64
Name Base: [2]weights1!$B$1:$T$60
Name bb: #REF!
Name bloomdur: '[4]Bloomberg duration lookup'!$A:$C
Name Bono: [2]weights1!$B$1:$T$60
Name Bonos: [2]weights1!$E$1:$T$60
Name Compra: [2]Hoja1!$A$1:$D$11
Name d: [5]IOControl!$E$2
Name DUR_TOTAL: [6]MATRIZ!#REF!
Name durationblm: #REF!
Name eqe: #REF!
Name fds: [7]IOControl!$E$4
Name flat: #REF!
Name Geldsaldo: #REF!
Name h: #REF!
Name i: #REF!
Name IITPIngMC: #REF!
Name instrumentos: '[3]BASE '!$E$2:$E$10
Name inter: '[3]BASE '!$D$2:$D$14
Name IO_CUR_COL: 1
Name IO_CUR_ROW: 7
Name klui: #REF!
Name MCC: [1]MATRIZ!#REF!
Name mog: #REF!
Name moneda: '[3]BASE '!$B$2:$B$4
Name PARM_Account: [8]IOControl!$E$2
Name PARM_To_Date: [8]IOControl!$E$4
Name qw: #REF!
Name s: Main.SAPF4Help()
Name SAPBEXrevision: 48
Name SAPBEXsysID: "CB3"
Name SAPBEXwbID: "3K38N8CGSBLCA6WS8HM7W6P8E"
Name SAPFuncF4Help: Main.SAPF4Help()
Name sd: [7]IOControl!$E$2
Name shit: #REF!
Name subinstrumento: '[3]BASE '!$F$2:$F$97
Name Switch: [2]Hoja1!$B$4:$D$27
Name tran: #REF!
Name TRAN_AD: #REF!
Name TRAN_AN_COL: #REF!
Name TRAN_AS_COL: #REF!
Name TRAN_CD_COL: #REF!
Name TRAN_CS_COL: #REF!
Name TRAN_CU_COL: #REF!
Name TRAN_CV_COL: #REF!
Name TRAN_DETAIL_ROW: #REF!
Name TRAN_ED_COL: #REF!
Name TRAN_G8_COL: #REF!

Sheet A Consol. Monac
B1: A. EJECUCIÓN CONSOLIDADA EN MONEDA NACIONAL
B2: (miles de pesos)
B3: Período: Diciembre 2023 - 2024
B5: INGRESOS | F5: Año 2023 | G5: Año 2024 | J5: GASTOS | N5: Año 2023 | O5: Año 2024
B7: IMPUESTOS | F7: 4.9874547e+10 | G7: 5.4790161e+10 | J7: SUBSIDIOS | N7: 2.4041425e+09 | O7: 2.2997657e+09
C8: Impuestos a la renta | F8: 2.5119144e+10 | G8: 2.5542707e+10 | K8: Prestaciones de Seguridad Social | N8: 1.5408148e+08 | O8: 1.6855228e+08
C9: Impuestos al valor agregado | F9: 2.3305166e+10 | G9: 2.5506569e+10 | K9: Transferencias corrientes | N9: 2.0518087e+09 | O9: 2.0309114e+09
C10: Impuestos a productos específicos | F10: 3.7179409e+09 | G10: 3.5352367e+09 | K10: Transferencias de capital | N10: 1.9825224e+08 | O10: 1.0030204e+08
C11: Impuestos a los actos jurídicos | F11: 7.4618917e+08 | G11: 7.7543058e+08
C12: Impuestos al comercio exterior | F12: 4.7913283e+08 | G12: 5.3389021e+08 | J12: OPERACIONES COMPLEMENTARIAS | N12: 3.7931229e+09 | O12: 4.657701e+09
C13: Impuestos varios | F13: 1.3670271e+09 | G13: 1.1553036e+09 | K13: Presentaciones de seg. social y Bienes de Consumo | N13: 1.2543006e+08 | O13: 1.1493536e+08
C14: Otros ingresos tributarios | F14: 4.5677616e+08 | G14: 4.8816198e+08 | K14: Transferencias corrientes y otros gastos | N14: 7.0759009e+08 | O14: 1.1311193e+09
C15: Sistema de pago de impuestos | F15: -5.3168294e+09 | G15: -2.7471376e+09 | K15: Adquisición de activos financieros | N15: 1.176776e+09 | O15: 7.7265649e+08
K16: Transferencias de capital y préstamos | N16: 1.7833267e+09 | O16: 2.6389899e+09
B17: TRANSFERENCIAS CORRIENTES | F17: 3.1775952e+09 | G17: 3.9370011e+09
B18: RENTAS DE LA PROPIEDAD | F18: 1.1270688e+09 | G18: 6.0338182e+08
B19: INGRESOS DE OPERACIÓN | F19: 50843934 | G19: 37349313 | J19: SERVICIO DE LA DEUDA | N19: 3.0220447e+09 | O19: 3.8497288e+09
B20: OTROS INGRESOS CORRIENTES | F20: 3.7988488e+09 | G20: 4.2900227e+09 | K20: Intereses deuda - interna | N20: 1.967442e+09 | O20: 2.405548e+09
C21: Multas e intereses no provenientes de impuestos | F21: 2.1409645e+08 | G21: 2.4388924e+08 | K21: Intereses deuda - externa | N21: 1.0484883e+09 | O21: 1.4388429e+09
C22: Otros | F22: 3.5847524e+09 | G22: 4.0461334e+09 | K22: Otros gastos Financieros Deuda Interna | N22: 1505570.5 | O22: 914631.67
D23: Devoluciones y reintegros no provenientes | F23: 4.4100963e+08 | G23: 3.9187564e+08 | K23: Otros gastos Financieros Deuda Externa | N23: 4608908.4 | O23: 4423331.9
D24: de impuestos
D25: Aporte Fdo. Retiro L.19.882 | F25: 0 | G25: 0
D26: Integros Ley N° 20.063 | F26: 0 | G26: 0
D27: Otros | F27: 3.1437427e+09 | G27: 3.6542578e+09 | J27: APORTE FISCAL LIBRE A ORGANISMOS PÚBLICOS | N27: 5.9649591e+10 | O27: 6.3273637e+10
B29: VENTA DE ACTIVOS NO FINANCIEROS | F29: 288097.39 | G29: 632189.36
B31: VENTA DE ACTIVOS FINANCIEROS | F31: 3.4047199e+09 | G31: 114093800
B32: RECUPERACIÓN DE PRÉSTAMOS | F32: 9945849.3 | G32: 52040629
B33: TRANSFERENCIAS PARA GASTOS DE CAPITAL | F33: 92496421 | G33: 94509792
B35: FONDO DE RESERVA DE PENSIONES | F35: 1.895041e+09 | G35: 1.1499983e+09 | J35: FONDO DE RESERVA DE PENSIONES | N35: 1.895041e+09 | O35: 1.1499983e+09
B36: FONDO ESTABILIZACIÓN ECONÓMICA SOCIAL | F36: 2.3161339e+09 | G36: 2.6492597e+09 | J36: FONDO DE ESTABILIZACIÓN ECONÓMICA Y SOCIAL | N36: 2.3161339e+09 | O36: 2.6492597e+09
B37: FONDO PARA LA EDUCACIÓN | F37: 3.8263532e+08 | G37: 0 | J37: FONDO PARA LA EDUCACIÓN | N37: 3.8263532e+08 | O37: 0
B38: FONDO DE APOYO REGIONAL | F38: 6.4644133e+08 | G38: 485068604 | J38: FONDO DE APOYO REGIONAL | N38: 6.4644133e+08 | O38: 485068604
B39: FONDO TRATAMIENTO ALTO COSTO | F39: 3.1302419e+08 | G39: 1.5404963e+08 | J39: FONDO TRATAMIENTO ALTO COSTO | N39: 3.1302419e+08 | O39: 1.5404963e+08
B40: EMPRESAS Y SOCIEDADES DEL ESTADO | F40: 565106379 | G40: 1097050356 | J40: EMPRESAS Y SOCIEDADES DEL ESTADO | N40: 565106379 | O40: 1097050356
B41: FONDO DE CONTINGENCIA ESTRATÉGICO | F41: 0 | G41: 0 | J41: FONDO DE CONTINGENCIA ESTRATÉGICO | N41: 0 | O41: 0
B42: FINANCIAMIENTO GOBIERNOS REGIONALES | F42: 0 | G42: 0 | J42: FINANCIAMIENTO GOBIERNOS REGIONALES | N42: 0 | O42: 0
B43: PROGRAMA DE BENEFICIOS FET - Covid - 19 | F43: 0 | G43: 0 | J43: PROGRAMA DE BENEFICIOS FET - Covid - 19 | N43: 0 | O43: 0
B45: SUBTOTAL | F45: 6.7654736e+10 | G45: 6.9454619e+10 | J45: SUBTOTAL | N45: 7.4987284e+10 | O45: 7.9616259e+10
B47: ENDEUDAMIENTO | F47: 1.9052932e+10 | G47: 2.7820543e+10 | J47: AMORTIZACIONES SERVICIO DE DEUDA | N47: 1.137733e+10 | O47: 1.6672083e+10
...

Sheet A.1 Ing Gen desg. Consolidado
B2: B. INGRESOS GENERALES - CONSOLIDADO
B3: DESAGREGADOS POR TIPO DE INGRESO - NIVEL NACIONAL
B4: (miles de pesos)
B5: Período: Ejercicio 2024 - 2023
B7: DENOMINACIÓN | F7: Ejecución anual 2023 | G7: Ejecución anual 2024 | H7: Var. %
B9: IMPUESTOS | F9: 5.5976947e+10 | G9: 5.4790161e+10 | H9: -2.1201341
C11: Impuestos a la renta | F11: 2.8103287e+10 | G11: 2.5542707e+10 | H11: -9.1113203
C12: Primera categoría; bienes raíces, agricultura, industria, comercio, minería,
C13: entidades financieras y otras | F13: 1.6288863e+10 | G13: 1.3698377e+10 | H13: -15.903418
C14: Segunda categoría; sueldos, salarios y pensiones | F14: 3.9140802e+09 | G14: 5.8039102e+09 | H14: 48.282861
C15: Global complementario | F15: 1.3091508e+09 | G15: 1.5144875e+09 | H15: 15.684719
C16: Adicional | F16: 3.648249e+09 | G16: 3.1243134e+09 | H16: -14.361289
C17: Tasa 40% DL N° 2.398 de 1978 | F17: 1.4141645e+09 | G17: 6.3389785e+08 | H17: -55.175099
C18: Artículo 21 ley de impuesto a la renta | F18: 1.0901406e+08 | G18: 1.2720422e+08 | H18: 16.686065
C19: Término de giro | F19: 47506520 | G19: 16703752 | H19: -64.839032
C20: Impuesto específico a la actividad minera | F20: 1.3722585e+09 | G20: 6.238124e+08 | H20: -54.54119
C21: Instrumento de Deuda Art. 104. N° Ley Renta | F21: 0 | G21: 0 | H21: 0
B24: Impuesto al valor agregado | F24: 2.2842833e+10 | G24: 2.5506569e+10 | H24: 11.661145
C25: Tasa General | F25: 6.0912691e+09 | G25: 1.0826075e+10 | H25: 77.731019
D26: Débitos del período | F26: 8.586185e+10 | G26: 9.4656568e+10 | H26: 10.242871
D27: Créditos del período | F27: -7.9770581e+10 | G27: -8.3830493e+10 | H27: 5.0894861
C30: Tasas especiales | F30: 6.4481431e+08 | G30: 6.8381921e+08 | H30: 6.0490124
D31: Débitos del período | F31: 1.1154343e+09 | G31: 1.1054691e+09 | H31: -0.89338653
D32: Créditos del período | F32: -4.7061998e+08 | G32: -4.2164994e+08 | H32: -10.405431
F33: 0 | G33: 0
C34: Tasa general de importaciones | F34: 1.610675e+10 | G34: 1.3996675e+10 | H34: -13.100561
B37: Impuestos a productos específicos | F37: 2.0045578e+09 | G37: 3.5352367e+09 | H37: 76.359925
C38: Tabacos, cigarros, cigarrillos | F38: 1.171363e+09 | G38: 9.6674209e+08 | H38: -17.468618
C39: Combustibles | F39: 8.331948e+08 | G39: 2.5684946e+09 | H39: 208.2706
D40: Derechos de explotación | F40: 80986.646 | G40: 3651834.1 | H40: 4409.1806
D41: Gasolina, petróleo diesel y otros | F41: 8.1154786e+08 | G41: 2.4944561e+09 | H41: 207.37018
D42: Derecho de extracción Ley de Pesca | F42: 21565959 | G42: 70386610 | H42: 226.37831
B45: Impuestos a los actos jurídicos | F45: 7.6570935e+08 | G45: 7.7543058e+08 | H45: 1.2695707
B48: Impuestos al comercio exterior | F48: 5.5271652e+08 | G48: 5.3389021e+08 | H48: -3.4061411
C49: Derechos específicos de interacción | F49: 89295.719 | G49: 162207.31 | H49: 81.651828
C50: Derechos ad valórem | F50: 5.9174478e+08 | G50: 5.5566994e+08 | H50: -6.0963507
C51: Otros | F51: 12476353 | G51: 23120602 | H51: 85.315394
C52: Sistema de pago | F52: -51593906 | G52: -45062535 | H52: -12.659191
B65: DENOMINACIÓN | F65: Ejecución anual 2023 | G65: Ejecución anual 2024 | H65: Var. %
B67: Impuestos varios | F67: 1.1225113e+09 | G67: 1.1553036e+09 | H67: 2.9213384
...

Sheet C Gts Gen desg. Consolidado
B1: C. GASTOS GENERALES - CONSOLIDADO
B2: DESAGREGADOS POR TIPO DE GASTO - NIVEL NACIONAL
B3: (miles de pesos)
B4: Período: Ejercicio 2024 - 2023
B6: DENOMINACIÓN | G6: Ejecución anual 2023 | H6: Ejecución anual 2024 | I6: Var. %
B8: SUBSIDIOS | G8: 2.8564599e+09 | H8: 2.2997657e+09 | I8: -19.488956
B10: PRESTACIONES DE SEGURIDAD SOCIAL | G10: 1.32818e+08 | H10: 1.6855228e+08 | I10: 26.904691
C11: Prestaciones Previsionales | G11: 1.32818e+08 | H11: 1.6855228e+08 | I11: 26.904691
D12: Jubilaciones, Pensiones y Montepíos | G12: 75573952 | H12: 98646971 | I12: 30.530385
D13: Fondo Bono Laboral Ley N° 20.305 | G13: 57244050 | H13: 69905305 | I13: 22.118028
B15: TRANSFERENCIAS CORRIENTE | G15: 2.5267373e+09 | H15: 2.0309114e+09 | I15: -19.623168
C16: Al sector privado | G16: 2.3115432e+09 | H16: 1.7598341e+09 | I16: -23.867564
D17: Subvenciones | G17: 3691711.2 | H17: 1451381.3 | I17: -60.685406
D18: Bonificación Región XII y la Antártica Chilena, y subsidio Isla de Pascua | G18: 27325170 | H18: 44769788 | I18: 63.840836
D19: Fondo único prestaciones familiares y subsidios de cesantía | G19: 573756966 | H19: 654044660 | I19: 13.993328
D20: Subsidio de cesantía art. 69 DFL (T. y P.S.) N° 150 de 1981 | G20: 0 | H20: 52.014 | I20: 0
D21: Fondo nacional de subsidio familiar | G21: 393171850 | H21: 632073540 | I21: 60.762664
D22: Subsidio agua potable Ley N° 18.778 | G22: 94677122 | H22: 1.012715e+08 | I22: 6.9651273
D23: Bonificación a la contratación mano de obra Ley N° 19.853 | G23: 75673593 | H23: 76839208 | I23: 1.5403192
D24: Beneficio Ley N°20.330 para Deudores Crédito Universitario, Leyes N°19.287 y 20.027 | G24: 379154.43 | H24: 464771.4 | I24: 22.581027
D25: Subsidio Temporal y Otras Medidas de Apoyo para las MIPYMES y Cooperativas ley N° 21.578 | G25: 0 | H25: 94501489 | I25: 0
D26: Aplicación Ley N° 20.765, Art. 3° N° 6) MEPCO | G26: 1.1428676e+09 | H26: 1.4193294e+08 | I26: -87.580981
D27: Subsidio Servicios Básicos Domiciliarios, ley N° 21.423 | G27: 0 | H27: 12484792 | I27: 0
I28: 0
C30: Al gobierno central | G30: 215194110 | H30: 271077265 | I30: 25.96872
D31: Fondo único de prestaciones familiares y subsidios de cesantía | G31: 121795614 | H31: 158957150 | I31: 30.511391
D32: Empresas y Sociedades del Estado | G32: 93398496 | H32: 112120115 | I32: 20.044883
B34: TRANSFERENCIAS DE CAPITAL | G34: 1.9690464e+08 | H34: 1.0030204e+08 | I34: -49.0606
C35: Al sector privado | G35: 1.2080048e+08 | H35: 1.0030204e+08 | I35: -16.968835
D36: Bonificación por inversiones de riego y drenaje | G36: 1.1656506e+08 | H36: 95223863 | I36: -18.308398
D37: Fondo fomento y desarrollo de regiones extremas | G37: 2659274.9 | H37: 3058621.3 | I37: 15.017117
D38: Bosque Nativo Ley N° 20.283 | G38: 1576144.6 | H38: 2019559.3 | I38: 28.13287
C40: Al sector privado | G40: 76104166 | H40: 0 | I40: -100
D41: Empresas y Sociedades del estado | G41: 76104166 | H41: 0 | I41: -100
B44: OPERACIONES COMPLEMENTARIAS | G44: 1.462964e+10 | H44: 4.657701e+09 | I44: -68.162573 | K44: 0.44658566
B46: BIENES Y SERVICIOS DE CONSUMO | G46: 427070.35 | H46: 35161082 | I46: 8133.0889
B48: PRESTACIONES DE SEGURIDAD SOCIAL | G48: 1.2202801e+08 | H48: 79774281 | I48: -34.626253
C49: Prestaciones previsionales | G49: 2777745.9 | H49: 0 | I49: -100
D50: Jubilaciones, pensiones y montepíos | G50: 0 | H50: 0 | I50: 0
D51: Fondo seguro social de los EE.PP. | G51: 2777745.9 | H51: 0 | I51: -100
...

Sheet VII A. Resumen Deuda
B2: D. RESUMEN DE LA DEUDA PÚBLICA DEL TESORO PÚBLICO
B3: DEUDA PÚBLICA
B4: SALDO AL 31 DE DICIEMBRE 2024
B5: (millones de pesos)
D7: INTERNA | F7: EXTERNA
B8: Detalle | D8: Saldos | E8: Distribución porcentual | F8: Saldos | G8: Distribución porcentual | H8: Saldos Totales
B10: Directa | D10: 82479472 | E10: =+D10/D12*100 -> 94.901731 | F10: 46791822 | G10: =+F10/F12*100 -> 100 | H10: =+D10+F10 -> 1.2927129e+08
B11: Indirecta * | D11: 4430925.9 | E11: =+D11/D12*100 -> 5.0982691 | F11: 0 | G11: =+F11/F12*100 -> 0 | H11: =+D11+F11 -> 4430925.9
B12: TOTAL | D12: =SUM(D10:D11) -> 86910398 | E12: =SUM(E10:E11) -> 100 | F12: =SUM(F10:F11) -> 46791822 | G12: =SUM(G10:G11) -> 100 | H12: =SUM(H10:H11) -> 1.3370222e+08
B14: % | D14: =+D12/H12*100 -> 65.002958 | F14: =+F12/H12*100 -> 34.997042 | H14: =+D14+F14 -> 100
B16: Elaboración propia División Finanzas Públicas, Sección Contabilidad Gubernamental.
B17: * Deuda con garantía del Fisco/Tesoro Público (Estado).
B21: Gráfico N°1
B22: SALDOS DEUDA PÚBLICA AL 31 DE DICIEMBE 2024
B49: STOCK DE DEUDA PÚBLICA INTERNA Y EXTERNA
B50: COMPARATIVO 2023 / 2024
B51: (millones de pesos)
C53: Interna | E53: Externa | G53: Total
C54: 2023 | D54: 2024 | E54: 2023 | F54: 2024 | G54: 2023 | H54: 2024
B55: Directa | C55: 70928142 | D55: =D10 -> 82479472 | E55: 35016061 | F55: =F10 -> 46791822 | G55: =C55+E55 -> 1.059442e+08 | H55: =D55+F55 -> 1.2927129e+08
B56: Indirecta | C56: 4504706.2 | D56: =D11 -> 4430925.9 | E56: 0 | F56: =F11 -> 0 | G56: =C56+E56 -> 4504706.2 | H56: =D56+F56 -> 4430925.9
B58: Total | C58: =SUM(C55:C56) -> 75432848 | D58: =SUM(D55:D56) -> 86910398 | E58: =SUM(E55:E56) -> 35016061 | F58: =SUM(F55:F56) -> 46791822 | G58: =SUM(G55:G56) -> 1.1044891e+08 | H58: =SUM(H55:H56) -> 1.3370222e+08
C59: Elaboración propia División Finanzas Públicas, Sección Contabilidad Gubernamental.
D71: Interna | E71: Externa
C72: Directa | D72: =+D10 -> 82479472 | E72: =+F10 -> 46791822
C73: Indirecta | D73: =+D11 -> 4430925.9 | E73: =+F11 -> 0

Sheet Resumen Inversiones
I1: T/C 30-12-2024 | J1: 992.12
B2: E. STOCK DE INVERSIONES DEL TESORO PÚBLICO | I2: T/C 30-12-2023 | J2: 884.59
B3: SALDO AL 31 DE DICIEMBRE | I3: T/C 30-12-2022 | J3: 859.51
B4: (millones de pesos)
C6: 2022 | D6: 2023 | E6: 2024
B8: Inversiones del Tesoro | C8: 3480526.5 | D8: 571746.37 | E8: 522590
B9: Subtotal Otros Activos TP | C9: =C8 -> 3480526.5 | D9: =D8 -> 571746.37 | E9: =E8 -> 522590
B11: Fondo de Educación (FE) | C11: 176435 | D11: 0 | E11: 0
B12: Fondo Tratamiento Alto Costo (TAC) | C12: 158595 | D12: 138970.49 | E12: 109946
B13: Fondo de Apoyo Regional (FAR) | C13: 219311 | D13: 383432.97 | E13: 464946
B14: Subtotal Fondos Especiales | C14: =SUM(C11:C13) -> 554341 | D14: =SUM(D11:D13) -> 522403.46 | E14: =SUM(E11:E13) -> 574892
B16: Fondo de Reserva de Pensiones (FRP) | C16: 5565564.1 | D16: 7641580.6 | E16: 9304389.1
B17: Fondo de Estabilización Económica y Social (FEES) | C17: 6458515 | D17: 5334176.5 | E17: 3589688.6
B18: Subtotal Fondos Soberanos | C18: =SUM(C16:C17) -> 12024079 | D18: =SUM(D16:D17) -> 12975757 | E18: =SUM(E16:E17) -> 12894078
B20: TOTAL INVERSIONES MM$ | C20: =C9+C14+C18 -> 16058947 | D20: =D9+D14+D18 -> 14069907 | E20: =E9+E14+E18 -> 13991560
B21: TOTAL INVERSIONES MUS$ | C21: =C20/$J$2 -> 18154.113 | D21: =D20/$J$2 -> 15905.569 | E21: =E20/$J$1 -> 14102.689
B26: SALDOS AL 31 DE DICIEMBRE POR MERCADO
B27: (millones de pesos)
C29: 2022 | D29: 2023 | E29: 2024
B30: MERCADO LOCAL
B31: - Inversiones del Tesoro | C31: 779502.87 | D31: 571746.37 | E31: 522590
B32: - Fondos Especiales | C32: 377906 | D32: 522403.46 | E32: 574892
B33: - Fondos Soberanos | C33: 0 | D33: 0 | E33: 0
B34: Subtotal Mercado Local | C34: =SUM(C31:C33) -> 1157408.9 | D34: =SUM(D31:D33) -> 1094149.8 | E34: =SUM(E31:E33) -> 1097482
B36: MERCADO INTERNACIONAL
B37: - Inversiones del Tesoro | C37: 2701023.6 | D37: 0 | E37: 0
B38: - Fondos Especiales | C38: 176435 | D38: 0 | E38: 0
B39: - Fondos Soberanos | C39: 12024079 | D39: 12975757 | E39: 12894078
B40: Subtotal Mercado Local | C40: =SUM(C37:C39) -> 14901538 | D40: =SUM(D37:D39) -> 12975757 | E40: =SUM(E37:E39) -> 12894078
B42: TOTAL INVERSIONES
B43: - Inversiones del Tesoro | C43: 3480526.5 | D43: 571746.37 | E43: 522590
B44: - Fondos Especiales | C44: 554341 | D44: 522403.46 | E44: 574892
B45: - Fondos Soberanos | C45: 12024079 | D45: 12975757 | E45: 12894078
B46: TOTAL INVERSIONES | C46: =SUM(C43:C45) -> 16058947 | D46: =SUM(D43:D45) -> 14069907 | E46: =SUM(E43:E45) -> 13991560
B48: Elaboración propia División Finanzas Públicas.
B49: Para la conversión de las cifras, se utilizó el tipo de cambio del último día mes de diciembre de cada año. Período 2024 por un valor de $992,12; período 2023 por un valor de $884,59; período 2022 por valor de $859,51.

Sheet VII B.1 E° Comp D Pub Dir Int
B1: D.1 DEUDA PÚBLICA INTERNA DEL TESORO PÚBLICO
B2: D.1.1 DIRECTA POR TIPO DE DOCUMENTO
B3: (miles de pesos)*
B5: DETALLE | C5: Saldo al 31.12.23 | D5: Saldo al 31.12.24 | E5: % Variación 23/24
B7: BTU0000325 | C7: 1.6386717e+09 | D7: 7.6841063e+08 | E7: 0
B8: BTU0260925 | C8: 16003372 | D8: 16711260 | E8: 0
B9: BTU0150326 | C9: 6.0906073e+09 | D9: 3.5619379e+09 | E9: =(D9-C9)*100/C9 -> -41.517525
B10: BTU0300327 | C10: 12839487 | D10: 13407425 | E10: =(D10-C10)*100/C10 -> 4.4233713
B11: BTU0300328 | C11: 11036808 | D11: 11525007 | E11: =(D11-C11)*100/C11 -> 4.4233713
B12: BTU0001028 | C12: 1.8795684e+09 | D12: 5.1540792e+09 | E12: =(D12-C12)*100/C12 -> 174.2161
B13: BTU0300329 | C13: 16849527 | D13: 17594844 | E13: =(D13-C13)*100/C13 -> 4.4233713
B14: BTU0300130 | C14: 53270993 | D14: 55627367 | E14: =(D14-C14)*100/C14 -> 4.4233713
B15: BTU0190930 | C15: 4.5785278e+09 | D15: 5.5301786e+09 | E15: =(D15-C15)*100/C15 -> 20.785082
B16: BTU0300132 | C16: 6180612.5 | D16: 6454003.9 | E16: =(D16-C16)*100/C16 -> 4.4233713
B17: BTU0001033 | C17: 3.2036175e+09 | D17: 3542018818 | E17: =(D17-C17)*100/C17 -> 10.563101
B18: BTU0300134 | C18: 6530111.4 | D18: 6818962.5 | E18: 0
B19: BTU0200335 | C19: 5.5463639e+09 | D19: 5.7917002e+09 | E19: =(D19-C19)*100/C19 -> 4.4233713
B20: BTU0300338 | C20: 81635590 | D20: 85246635 | E20: =(D20-C20)*100/C20 -> 4.4233713
B21: BTU0300339 | C21: 98429933 | D21: 1.0278385e+08 | E21: 0
B22: BTU0300140 | C22: 56398089 | D22: 58892786 | E22: =(D22-C22)*100/C22 -> 4.4233713
B23: BTU0300142 | C23: 9638812.3 | D23: 10065173 | E23: =(D23-C23)*100/C23 -> 4.4233713
B24: BTU0300144 | C24: 6653355756 | D24: 7.2396252e+09 | E24: =(D24-C24)*100/C24 -> 8.8116358
B25: BTU0210750 | C25: 3.9586639e+09 | D25: 4.5164005e+09 | E25: =(D25-C25)*100/C25 -> 14.089012
B26: BTU0281155 | C26: 51872998 | D26: 918158891 | E26: =(D26-C26)*100/C26 -> 1670.0132
B27: BTU0341039 | C27: 9841153.8 | D27: 922000560 | E27: =(D27-C27)*100/C27 -> 9268.8258
B28: SUBTOTAL BONOS DE LA TESORERIA GENERAL EN PESOS (BTU) | C28: =SUM(C7:C27) -> 3.3979904e+10 | D28: =SUM(D7:D27) -> 3.8329638e+10 | E28: =(D28-C28)*100/C28 -> 12.800902
B31: DETALLE | C31: =+C5 -> Saldo al 31.12.23 | D31: =+D5 -> Saldo al 31.12.24 | E31: =+E5 -> % Variación 23/24
B33: BTP0250325 | C33: 5498380000 | D33: 2139285000 | E33: =(D33-C33)*100/C33 -> -61.092449
B34: BTP0450326 | C34: 3320825000 | D34: 1157520000 | E34: =(D34-C34)*100/C34 -> -65.143601
B35: BTP0000527 | C35: 0 | D35: 3366745000 | E35: 0
B36: BTP0491127 | C36: 0 | D36: 940075000 | E36: 0
B37: BTP0000429 | C37: 0 | D37: 4376510000 | E37: 0
B38: BTP0581029 | C38: 0 | D38: 2202570000 | E38: 0
B39: BTP0470930 | C39: 3870780000 | D39: 4575780000 | E39: =(D39-C39)*100/C39 -> 18.213383
B40: BTP0600132 | C40: 2050000 | D40: 2050000 | E40: =(D40-C40)*100/C40 -> 0
B41: BTP0600134 | C41: 0 | D41: 3650000 | E41: 0
B42: BTP0500335 | C42: 4120200000 | D42: 4120200000 | E42: =(D42-C42)*100/C42 -> 0
B43: BTP0600143 | C43: 3397970000 | D43: 3397970000 | E43: =(D43-C43)*100/C43 -> 0
B44: BTP0510750 | C44: 2400565000 | D44: 2720565000 | E44: =(D44-C44)*100/C44 -> 13.330195
B45: BTP0610456 | C45: 0 | D45: 621600000 | E45: 0
...

Sheet VII B.2 E° Comp D Pub Ind Int
B2: D.1 DEUDA PÚBLICA INTERNA DEL TESORO PÚBLICO
B3: D.1.2 INDIRECTA POR DEUDOR
B4: (millones de pesos)*
B7: DETALLE | D7: Moneda | E7: Saldo al 31.12.23 | F7: Saldo al 31.12.24 | G7: % Variación 23/24
B9: FF.CC. Del Estado | D9: UF | E9: 1716515.3 | F9: 1785928.8 | G9: =((F9/E9)-1)*100 -> 4.0438598
B10: Metro | D10: UF | E10: 454647.48 | F10: 390025.41 | G10: =((F10/E10)-1)*100 -> -14.213664
B11: Universidad de Chile | D11: UF | E11: 6093.3709 | F11: 6362.9033 | G11: =((F11/E11)-1)*100 -> 4.4233713
B12: Créditos de Educacion Superior | D12: UF | E12: 2214847.4 | F12: 2143151.8 | G12: =((F12/E12)-1)*100 -> -3.2370456
B13: TVN | D13: UF | E13: 62986.118 | F13: 65772.228 | G13: =((F13/E13)-1)*100 -> 4.4233713
B14: Empresa Nacional de Aeronautica | D14: Dólar | E14: 49616.483 | F14: 39684.8 | G14: =((F14/E14)-1)*100 -> -20.016902
B16: TOTAL | E16: =SUM(E9:E15) -> 4504706.2 | F16: =SUM(F9:F15) -> 4430925.9 | G16: =((F16/E16)-1)*100 -> -1.6378483
B18: Elaboración propia División Finanzas Públicas, Sección Contabilidad Gubernamental.
B20: Para la conversión de las cifras, se utilizó el valor de la UF al 31 de Diciembre de 2024 por un valor de $38.416,69 y el tipo de cambio del día 30 de diciembre de 2023 por un valor de $992,12.

Sheet VII C.1 Comp D Pub Dir Ext Acr 
B2: D.2. DEUDA PÚBLICA EXTERNA DEL TESORO PÚBLICO
B3: D.2.1 DIRECTA POR ACREEDOR
B4: (miles de pesos)
D6: Saldo al 31.12.23 | E6: Saldo al 30.12.24 | F6: % Var. 23/24
B7: DETALLE
B8: Organismos Multinacionales Oficiales | D8: 2.1217829e+09 | E8: 2.4773239e+09 | F8: =((E8/D8)-1)*100 -> 16.756709
B9: Organismos Gubernamentales (No Reestructurados) | D9: 51768044 | E9: 36807491 | F9: =((E9/D9)-1)*100 -> -28.899204
B10: Empréstitos de otros acreedores | D10: 0 | E10: 0 | F10: 0
B11: Bonos Emitidos en el Exterior | D11: 3.7242101e+10 | E11: 4.4277691e+10 | F11: =((E11/D11)-1)*100 -> 18.891496
B13: TOTAL | D13: =SUM(D8:D12) -> 3.9415652e+10 | E13: =SUM(E8:E12) -> 4.6791822e+10 | F13: =((E13/D13)-1)*100 -> 18.713811
B15: Elaboración propia División Finanzas Públicas.
B16: Para la conversión de las cifras, se utilizó el valor del dólar al 30 de Diciembre de 2023 y 30 de Diciembre 2024 por un valor de $884,59 y $992,12 respectivamente.
B21: DEUDA PUBLICA EXTERNA DEL TESORO
B22: DETALLE POR BANCO
B23: (miles de pesos)
B26: BANCO | D26: =D6 -> Saldo al 31.12.23 | E26: =E6 -> Saldo al 30.12.24
B28: BID | D28: 2.033545e+09 | E28: 2.3781119e+09
B29: BIRF | D29: 88237852 | E29: 99212000
B30: Total Organismos Multinacionales Oficiales | D30: =SUM(D28:D29) -> 2.1217829e+09 | E30: =SUM(E28:E29) -> 2.4773239e+09
B32: KFW | D32: 40385426 | E32: 27447437
B33: Natixis Banque | D33: 11379223 | E33: 9360054
B34: SIDA | D34: 0 | E34: 0
B35: ICO | D35: 3394.5522 | E35: 0
B36: Banca Nazionale del Lavoro | D36: 0 | E36: 0
B37: Total Organismos Gubernamentales (No Reestructurados) | D37: =SUM(D32:D36) -> 51768044 | E37: =SUM(E32:E36) -> 36807491
B39: Bono Soberano JP Morgan Chase Bank | D39: 0 | E39: 0
B40: Bono Soberano Deutsche Bank Securities / HSBC | D40: 0 | E40: 0
B41: Bono Soberano the Bank of New York Mellon | D41: 3.7242101e+10 | E41: 4.4277691e+10
B42: Bono Soberano Citigroup, HSBC y Santander | D42: 0 | E42: 0
B43: Bono Soberano Citigroup, Merril Lynch | D43: 0 | E43: 0
B44: Total Bonos Emitidos en el Exterior | D44: =SUM(D39:D43) -> 3.7242101e+10 | E44: =SUM(E39:E43) -> 4.4277691e+10
B46: Para la conversión de las cifras, se utilizó el valor del dólar al 30 de Diciembre de 2023 y 30 de Diciembre 2024 por un valor de $884,59 y $992,12 respectivamente.
D55: =D30+D37+D44 -> 3.9415652e+10 | E55: =E30+E37+E44 -> 4.6791822e+10
D56: =+D13 -> 3.9415652e+10 | E56: =+E13 -> 4.6791822e+10
B57: Dif. | D57: =+D55-D56 -> 0 | E57: =+E55-E56 -> 0

Sheet VII C.2 Comp D Pub Dir Ext Geo 
B2: D.2 DEUDA PÚBLICA EXTERNA DEL TESORO PÚBLICO
B3: D.2.2 DIRECTA SEGÚN AREAS GEOGRÁFICAS
B4: (miles de pesos)
B6: Areas de los Acreedores | D6: Saldo al 31.12.23 | F6: Saldo al 31.12.24 | H6: % Variación 23/24
B7: Norteamérica | D7: =+'VII C.1 Comp D Pub Dir Ext Acr '!D11 -> 3.7242101e+10 | F7: =+'VII C.1 Comp D Pub Dir Ext Acr '!E11 -> 4.4277691e+10 | H7: =((F7/D7)-1)*100 -> 18.891496
B8: Europa | D8: =+'VII C.1 Comp D Pub Dir Ext Acr '!D9 -> 51768044 | F8: =+'VII C.1 Comp D Pub Dir Ext Acr '!E9 -> 36807491 | H8: =((F8/D8)-1)*100 -> -28.899204
B9: Multinacionales | D9: =+'VII C.1 Comp D Pub Dir Ext Acr '!D8 -> 2.1217829e+09 | F9: =+'VII C.1 Comp D Pub Dir Ext Acr '!E8 -> 2.4773239e+09 | H9: =((F9/D9)-1)*100 -> 16.756709
B11: TOTAL | D11: =SUM(D7:D10) -> 3.9415652e+10 | F11: =SUM(F7:F10) -> 4.6791822e+10 | H11: =((F11/D11)-1)*100 -> 18.713811
B13: Elaboración propia División Finanzas Públicas.
D18: Gráfico N° 7
D19: CORPORATIVO DE LOS SALDOS
D20: (millones de pesos)
E46: 31 de Diciembre 2023 | F46: 31 de Diciembre 2024
D47: Norteamérica | E47: =D7 -> 3.7242101e+10 | F47: =F7 -> 4.4277691e+10
D48: Europa | E48: =D8 -> 51768044 | F48: =F8 -> 36807491
D49: Multinacionales | E49: =D9 -> 2.1217829e+09 | F49: =F9 -> 2.4773239e+09
D50: Total | E50: =SUM(E47:E49) -> 3.9415652e+10 | F50: =SUM(F47:F49) -> 4.6791822e+10
